<?xml version="1.0"?>
<robot xmlns:xacro="http://www.ros.org/xacro/wiki" name="diffbot">

    <material name="body_dark_gray">
        <color rgba="0.2 0.2 0.2 1.0" />
    </material>

    <material name="accent_blue">
        <color rgba="0.0 0.45 0.85 1.0" />
    </material>

    <material name="wheel_black">
        <color rgba="0.05 0.05 0.05 1.0" />
    </material>

    <material name="metal_silver">
        <color rgba="0.7 0.7 0.7 1.0" />
    </material>


    <link name="base_footprint" />
    <link name="base_link">
        <visual>
            <origin rpy="0 0 0" xyz="0 0 0" />
            <geometry>
                <mesh filename="package://diffbot_description/meshes/base_link.STL" />
            </geometry>
            <material name="body_dark_gray" />
        </visual>
    </link>

    <joint name="base_joint" type="fixed">
        <parent link="base_footprint" />
        <child link="base_link" />
        <origin rpy="0 0 0" xyz="0 0 0.033" />
    </joint>

    <link name="wheel_right_link">
        <visual>
            <origin rpy="1.57 0 0" xyz="0 0 0" />
            <geometry>
                <mesh filename="package://diffbot_description/meshes/wheel_right_link.STL" />
            </geometry>
            <material name="wheel_black"/>
        </visual>
    </link>

    <joint name="wheel_right_joint" type="continuous">
        <parent link="base_link" />
        <child link="wheel_right_link" />
        <axis xyz="0 1 0" />
        <origin rpy="0 0 0" xyz="0 -0.0701101849418637 0" />
    </joint>

    <link name="wheel_left_link">
        <visual>
            <origin rpy="-1.57 0 0" xyz="0 0 0" />
            <geometry>
                <mesh filename="package://diffbot_description/meshes/wheel_left_link.STL" />
            </geometry>
            <material name="wheel_black"/>
        </visual>
    </link>

    <joint name="wheel_left_joint" type="continuous">
        <parent link="base_link" />
        <child link="wheel_left_link" />
        <axis xyz="0 1 0" />
        <origin rpy="0 0 0" xyz="0 0.0701101849418637 0" />
    </joint>

    <link name="caster_front_link">
        <visual>
            <origin rpy="0 0 0" xyz="0 0 0" />
            <geometry>
                <mesh filename="package://diffbot_description/meshes/caster_front_link.STL" />
            </geometry>
            <material name="metal_silver"/>
        </visual>
    </link>

    <joint name="caster_front_joint" type="fixed">
        <parent link="base_link" />
        <child link="caster_front_link" />
        <origin rpy="0 0 0" xyz="0.04755 0 -0.0275" />
    </joint>

    <link name="caster_rear_link">
        <visual>
            <origin rpy="0 0 0" xyz="0 0 0" />
            <geometry>
                <mesh filename="package://diffbot_description/meshes/caster_rear_link.STL" />
            </geometry>
            <material name="metal_silver"/>
        </visual>
    </link>

    <joint name="caster_rear_joint" type="fixed">
        <parent link="base_link" />
        <child link="caster_rear_link" />
        <origin rpy="0 0 0" xyz="-0.04755 0 -0.0275" />
    </joint>

</robot>